---
title: Simplify Your Promises with Promise.try()
menu_order: 3
post_status: publish
featured_image: _images/post-background.png
taxonomy:
  category:
    - javascript
  post_tag:
    - javascript
    - promise
    - asynchronous
    - error handling
---

<div class="toc" markdown="1">

## On this Page
* [The Challenge with Synchronous Callbacks in Promises](#the-challenge-with-synchronous-callbacks-in-promises)
* [Enter `Promise.try()`: Your New Helper](#enter-promisetry-your-new-helper)
* [How `Promise.try()` Works its Magic](#how-promisetry-works-its-magic)
* [`Promise.try()` in Action: Examples](#promisetry-in-action-examples)
    * [Basic Usage](#basic-usage)
    * [Handling Arguments](#handling-arguments)
    * [Comparison with `async/await`](#comparison-with-asyncawait)
* [Why `Promise.try()` is a Big Deal](#why-promisetry-is-a-big-deal)
* [Browser Support: It's Baseline!](#browser-support-its-baseline)
* [Wrapping Up: Cleaner Code, Happier Developer!](#wrapping-up-cleaner-code-happier-developer)

</div>

<div class="guru-main" markdown="1">

## Simplify Your Promises with `Promise.try()`: The New Way to Handle Callbacks!

Hey JavaScript developers! ðŸ‘‹ Ever found yourself scratching your head about how to consistently handle the results of callbacks within your Promise chains, especially when those callbacks might be synchronous or asynchronous? Well, get excited! A handy new tool called `Promise.try()` has just reached **Baseline Newly available** in all major browsers as of January 27, 2025!



### The Challenge with Synchronous Callbacks in Promises

Imagine you have a function that takes a callback. This callback might perform a quick, synchronous operation or it might involve asynchronous tasks. When you try to wrap its result in a Promise, you might instinctively do something like this:

```javascript
function executeCallback(callback) {
  return Promise.resolve(callback()); // Uh oh! Potential issue here
}

function syncOperation() {
  return "Synchronous result!";
}

function syncError() {
  throw new Error("Something went wrong synchronously!");
}

executeCallback(syncOperation)
  .then(result => console.log(result)) // Output: Synchronous result!
  .catch(error => console.error(error));

executeCallback(syncError)
  .then(result => console.log(result))
  .catch(error => console.error(error)); // This won't catch the synchronous error!
```

The problem here is that if `callback()` throws an error *synchronously*, `Promise.resolve()` won't catch it, and your `catch()` block won't be triggered. This can lead to unhandled exceptions and unexpected behavior in your application.

### Enter `Promise.try()`: Your New Helper

`Promise.try()` is a static method that takes any kind of callback function (one that returns a value, throws an error, or returns a Promise) and neatly wraps its result within a Promise. This provides a consistent way to handle both synchronous and asynchronous outcomes.

```javascript
function executeCallbackWithTry(callback) {
  return Promise.try(callback); // Much better!
}

function syncOperation() {
  return "Synchronous result!";
}

function syncError() {
  throw new Error("Something went wrong synchronously!");
}

executeCallbackWithTry(syncOperation)
  .then(result => console.log(result)) // Output: Synchronous result!
  .catch(error => console.error(error));

executeCallbackWithTry(syncError)
  .then(result => console.log(result))
  .catch(error => console.error(error)); // Now this will catch the synchronous error!
  // Output: Error: Something went wrong synchronously!
```

See the difference? `Promise.try()` gracefully catches synchronous errors and turns them into rejected Promises, allowing your Promise chain's error handling to work as expected.

### How `Promise.try()` Works its Magic

Under the hood, `Promise.try()` is similar to creating a new Promise and immediately resolving the result of your function within a `try...catch` block:

```javascript
Promise.try = function (func, ...args) {
  return new Promise((resolve, reject) => {
    try {
      resolve(func(...args));
    } catch (error) {
      reject(error);
    }
  });
};
```

This ensures that if `func()` executes without throwing, its return value is resolved. If it throws an error, that error is caught and the Promise is rejected.

### `Promise.try()` in Action: Examples

Let's look at some practical examples of how you can use `Promise.try()`:

#### Basic Usage

```javascript
function fetchData() {
  // This might be synchronous or asynchronous
  if (Math.random() > 0.5) {
    return "Data fetched successfully!";
  } else {
    throw new Error("Failed to fetch data.");
  }
}

Promise.try(fetchData)
  .then(result => console.log("Success:", result))
  .catch(error => console.error("Error:", error))
  .finally(() => console.log("Operation complete."));
```

#### Handling Arguments

Just like `setTimeout()`, `Promise.try()` can accept additional arguments that will be passed to your callback function:

```javascript
function processData(item1, item2) {
  return `Processed: ${item1} and ${item2}`;
}

Promise.try(processData, "apple", "banana")
  .then(result => console.log(result)); // Output: Processed: apple and banana

// Equivalent to:
Promise.try(() => processData("apple", "banana"))
  .then(result => console.log(result));
```

The first approach is often cleaner and avoids creating an unnecessary extra function.

#### Comparison with `async/await`

If you're using `async/await`, you typically handle synchronous errors with a `try...catch` block directly within your `async` function, so `Promise.try()` might not be as frequently used in those contexts for simple synchronous operations.

```javascript
async function doSomethingAsync(action) {
  try {
    const result = await action();
    console.log("Async result:", result);
  } catch (error) {
    console.error("Async error:", error);
  } finally {
    console.log("Async operation done.");
  }
}

doSomethingAsync(async () => "Async success!");
doSomethingAsync(async () => { throw new Error("Async fail!"); });
```

However, `Promise.try()` shines when you're dealing with functions that might *synchronously* throw errors within a Promise chain, helping you maintain consistent error handling.

### Why `Promise.try()` is a Big Deal

`Promise.try()` offers several advantages:

  * **Consistent Error Handling:** It ensures that both synchronous and asynchronous errors from your callbacks are caught and handled within your Promise chain's `catch()` method.
  * **Cleaner Code:** It can simplify your code, especially when dealing with utility functions that accept potentially synchronous callbacks.
  * **Improved Readability:** It makes it clearer that you're intentionally handling the result of a callback as a Promise, regardless of its synchronous or asynchronous nature.

### Browser Support: It's Baseline!

The fantastic news is that `Promise.try()` is now **Baseline Newly available**, meaning it's supported in all major modern browser engines. You can confidently start using it in your web applications knowing that it's a stable and interoperable part of the web platform.



### Wrapping Up: Cleaner Code, Happier Developer!

`Promise.try()` is a small but mighty addition to the JavaScript Promise API. It provides a more robust and convenient way to handle callbacks that might be synchronous, ensuring consistent error handling and cleaner code. So, next time you find yourself dealing with callbacks in your Promise chains, remember `Promise.try()` â€“ it might just become your new favorite tool!

Master the Code, Be the Guru!


</div>
